2023-07-11 13:37:17,947 INFO    StreamThr :1667 [internal.py:wandb_internal():86] W&B internal server running at pid: 1667, started at: 2023-07-11 13:37:17.946552
2023-07-11 13:37:17,960 DEBUG   HandlerThread:1667 [handler.py:handle_request():144] handle_request: status
2023-07-11 13:37:18,027 INFO    WriterThread:1667 [datastore.py:open_for_write():85] open: /Users/sohrabnamazinia/Desktop/Summer 23/RA/RL/RL_Modular/wandb/run-20230711_133717-c16308ow/run-c16308ow.wandb
2023-07-11 13:37:18,032 DEBUG   SenderThread:1667 [sender.py:send():369] send: header
2023-07-11 13:37:18,098 DEBUG   SenderThread:1667 [sender.py:send():369] send: run
2023-07-11 13:37:18,307 ERROR   SenderThread:1667 [internal_api.py:execute():324] 404 response executing GraphQL.
2023-07-11 13:37:18,307 ERROR   SenderThread:1667 [internal_api.py:execute():325] {"errors":[{"message":"project not found","path":["upsertBucket"]}],"data":{"upsertBucket":null}}
2023-07-11 13:37:18,308 ERROR   SenderThread:1667 [sender.py:send_run():955] It appears that you do not have permission to access the requested resource. Please reach out to the project owner to grant you access. If you have the correct permissions, verify that there are no issues with your networking setup.(Error 404: Not Found)
Traceback (most recent call last):
  File "/Library/Frameworks/Python.framework/Versions/3.11/lib/python3.11/site-packages/wandb/sdk/lib/retry.py", line 131, in __call__
    result = self._call_fn(*args, **kwargs)
             ^^^^^^^^^^^^^^^^^^^^^^^^^^^^^^
  File "/Library/Frameworks/Python.framework/Versions/3.11/lib/python3.11/site-packages/wandb/sdk/internal/internal_api.py", line 321, in execute
    return self.client.execute(*args, **kwargs)  # type: ignore
           ^^^^^^^^^^^^^^^^^^^^^^^^^^^^^^^^^^^^
  File "/Library/Frameworks/Python.framework/Versions/3.11/lib/python3.11/site-packages/wandb/vendor/gql-0.2.0/wandb_gql/client.py", line 52, in execute
    result = self._get_result(document, *args, **kwargs)
             ^^^^^^^^^^^^^^^^^^^^^^^^^^^^^^^^^^^^^^^^^^^
  File "/Library/Frameworks/Python.framework/Versions/3.11/lib/python3.11/site-packages/wandb/vendor/gql-0.2.0/wandb_gql/client.py", line 60, in _get_result
    return self.transport.execute(document, *args, **kwargs)
           ^^^^^^^^^^^^^^^^^^^^^^^^^^^^^^^^^^^^^^^^^^^^^^^^^
  File "/Library/Frameworks/Python.framework/Versions/3.11/lib/python3.11/site-packages/wandb/sdk/lib/gql_request.py", line 56, in execute
    request.raise_for_status()
  File "/Library/Frameworks/Python.framework/Versions/3.11/lib/python3.11/site-packages/requests/models.py", line 1021, in raise_for_status
    raise HTTPError(http_error_msg, response=self)
requests.exceptions.HTTPError: 404 Client Error: Not Found for url: https://api.wandb.ai/graphql

During handling of the above exception, another exception occurred:

Traceback (most recent call last):
  File "/Library/Frameworks/Python.framework/Versions/3.11/lib/python3.11/site-packages/wandb/sdk/internal/sender.py", line 953, in send_run
    self._init_run(run, config_value_dict)
  File "/Library/Frameworks/Python.framework/Versions/3.11/lib/python3.11/site-packages/wandb/sdk/internal/sender.py", line 991, in _init_run
    server_run, inserted, server_messages = self._api.upsert_run(
                                            ^^^^^^^^^^^^^^^^^^^^^
  File "/Library/Frameworks/Python.framework/Versions/3.11/lib/python3.11/site-packages/wandb/apis/normalize.py", line 73, in wrapper
    raise err
  File "/Library/Frameworks/Python.framework/Versions/3.11/lib/python3.11/site-packages/wandb/apis/normalize.py", line 41, in wrapper
    return func(*args, **kwargs)
           ^^^^^^^^^^^^^^^^^^^^^
  File "/Library/Frameworks/Python.framework/Versions/3.11/lib/python3.11/site-packages/wandb/sdk/internal/internal_api.py", line 1822, in upsert_run
    response = self.gql(
               ^^^^^^^^^
  File "/Library/Frameworks/Python.framework/Versions/3.11/lib/python3.11/site-packages/wandb/sdk/internal/internal_api.py", line 293, in gql
    ret = self._retry_gql(
          ^^^^^^^^^^^^^^^^
  File "/Library/Frameworks/Python.framework/Versions/3.11/lib/python3.11/site-packages/wandb/sdk/lib/retry.py", line 147, in __call__
    retry_timedelta_triggered = check_retry_fn(e)
                                ^^^^^^^^^^^^^^^^^
  File "/Library/Frameworks/Python.framework/Versions/3.11/lib/python3.11/site-packages/wandb/util.py", line 946, in check_retry_fn
    return fallback_retry_fn(e)
           ^^^^^^^^^^^^^^^^^^^^
  File "/Library/Frameworks/Python.framework/Versions/3.11/lib/python3.11/site-packages/wandb/util.py", line 888, in no_retry_auth
    raise CommError(
wandb.errors.CommError: It appears that you do not have permission to access the requested resource. Please reach out to the project owner to grant you access. If you have the correct permissions, verify that there are no issues with your networking setup.(Error 404: Not Found)
2023-07-11 13:37:18,518 DEBUG   HandlerThread:1667 [handler.py:handle_request():144] handle_request: shutdown
2023-07-11 13:37:18,518 INFO    HandlerThread:1667 [handler.py:finish():854] shutting down handler
2023-07-11 13:37:19,100 INFO    WriterThread:1667 [datastore.py:close():298] close: /Users/sohrabnamazinia/Desktop/Summer 23/RA/RL/RL_Modular/wandb/run-20230711_133717-c16308ow/run-c16308ow.wandb
2023-07-11 13:37:19,343 INFO    SenderThread:1667 [sender.py:finish():1526] shutting down sender
