2023-07-25 01:56:50,671 INFO    StreamThr :14164 [internal.py:wandb_internal():89] W&B internal server running at pid: 14164, started at: 2023-07-25 01:56:50.663768
2023-07-25 01:56:50,671 DEBUG   HandlerThread:14164 [handler.py:handle_request():144] handle_request: status
2023-07-25 01:56:50,711 INFO    WriterThread:14164 [datastore.py:open_for_write():85] open: C:\Users\ferti\Documents\RL_Modular\wandb\run-20230725_015650-trjja7vt\run-trjja7vt.wandb
2023-07-25 01:56:50,711 DEBUG   SenderThread:14164 [sender.py:send():379] send: header
2023-07-25 01:56:50,815 DEBUG   SenderThread:14164 [sender.py:send():379] send: run
2023-07-25 01:56:52,182 ERROR   SenderThread:14164 [internal_api.py:execute():325] 404 response executing GraphQL.
2023-07-25 01:56:52,182 ERROR   SenderThread:14164 [internal_api.py:execute():326] {"errors":[{"message":"project not found","path":["upsertBucket"]}],"data":{"upsertBucket":null}}
2023-07-25 01:56:52,198 ERROR   SenderThread:14164 [sender.py:send_run():976] It appears that you do not have permission to access the requested resource. Please reach out to the project owner to grant you access. If you have the correct permissions, verify that there are no issues with your networking setup.(Error 404: Not Found)
Traceback (most recent call last):
  File "C:\Users\ferti\AppData\Local\Programs\Python\Python36\lib\site-packages\wandb\sdk\lib\retry.py", line 131, in __call__
    result = self._call_fn(*args, **kwargs)
  File "C:\Users\ferti\AppData\Local\Programs\Python\Python36\lib\site-packages\wandb\sdk\internal\internal_api.py", line 322, in execute
    return self.client.execute(*args, **kwargs)  # type: ignore
  File "C:\Users\ferti\AppData\Local\Programs\Python\Python36\lib\site-packages\wandb\vendor\gql-0.2.0\wandb_gql\client.py", line 52, in execute
    result = self._get_result(document, *args, **kwargs)
  File "C:\Users\ferti\AppData\Local\Programs\Python\Python36\lib\site-packages\wandb\vendor\gql-0.2.0\wandb_gql\client.py", line 60, in _get_result
    return self.transport.execute(document, *args, **kwargs)
  File "C:\Users\ferti\AppData\Local\Programs\Python\Python36\lib\site-packages\wandb\sdk\lib\gql_request.py", line 56, in execute
    request.raise_for_status()
  File "C:\Users\ferti\AppData\Local\Programs\Python\Python36\lib\site-packages\requests\models.py", line 960, in raise_for_status
    raise HTTPError(http_error_msg, response=self)
requests.exceptions.HTTPError: 404 Client Error: Not Found for url: https://api.wandb.ai/graphql

During handling of the above exception, another exception occurred:

Traceback (most recent call last):
  File "C:\Users\ferti\AppData\Local\Programs\Python\Python36\lib\site-packages\wandb\sdk\internal\sender.py", line 974, in send_run
    self._init_run(run, config_value_dict)
  File "C:\Users\ferti\AppData\Local\Programs\Python\Python36\lib\site-packages\wandb\sdk\internal\sender.py", line 1026, in _init_run
    commit=run.git.commit or None,
  File "C:\Users\ferti\AppData\Local\Programs\Python\Python36\lib\site-packages\wandb\apis\normalize.py", line 73, in wrapper
    raise err
  File "C:\Users\ferti\AppData\Local\Programs\Python\Python36\lib\site-packages\wandb\apis\normalize.py", line 41, in wrapper
    return func(*args, **kwargs)
  File "C:\Users\ferti\AppData\Local\Programs\Python\Python36\lib\site-packages\wandb\sdk\internal\internal_api.py", line 1829, in upsert_run
    **kwargs,
  File "C:\Users\ferti\AppData\Local\Programs\Python\Python36\lib\site-packages\wandb\sdk\internal\internal_api.py", line 297, in gql
    **kwargs,
  File "C:\Users\ferti\AppData\Local\Programs\Python\Python36\lib\site-packages\wandb\sdk\lib\retry.py", line 147, in __call__
    retry_timedelta_triggered = check_retry_fn(e)
  File "C:\Users\ferti\AppData\Local\Programs\Python\Python36\lib\site-packages\wandb\util.py", line 950, in check_retry_fn
    return fallback_retry_fn(e)
  File "C:\Users\ferti\AppData\Local\Programs\Python\Python36\lib\site-packages\wandb\util.py", line 893, in no_retry_auth
    "It appears that you do not have permission to access the requested resource. "
wandb.errors.CommError: It appears that you do not have permission to access the requested resource. Please reach out to the project owner to grant you access. If you have the correct permissions, verify that there are no issues with your networking setup.(Error 404: Not Found)
2023-07-25 01:56:52,775 DEBUG   HandlerThread:14164 [handler.py:handle_request():144] handle_request: shutdown
2023-07-25 01:56:52,775 INFO    HandlerThread:14164 [handler.py:finish():857] shutting down handler
2023-07-25 01:56:52,831 INFO    WriterThread:14164 [datastore.py:close():294] close: C:\Users\ferti\Documents\RL_Modular\wandb\run-20230725_015650-trjja7vt\run-trjja7vt.wandb
2023-07-25 01:56:53,396 INFO    SenderThread:14164 [sender.py:finish():1552] shutting down sender
